<?xml version="1.0" encoding="utf-8"?>
<!-- This URDF was automatically created by SolidWorks to URDF Exporter! Originally created by Stephen Brawner (brawner@gmail.com) 
     Commit Version: 1.6.0-4-g7f85cfe  Build Version: 1.6.7995.38578
     For more information, please see http://wiki.ros.org/sw_urdf_exporter -->
<robot name="ino_ir_400_4">
  <link name="baselink">
    <inertial>
      <origin xyz="-0.0475269893399034 -9.18909934732606E-05 -0.063117944265121" rpy="0 0 0" />
      <mass
        value="2.90339245640769" />
      <inertia
        ixx="0.00973437418999566"
        ixy="-2.78454910615506E-05"
        ixz="0.000205437268202328"
        iyy="0.0147351913262812"
        iyz="-1.24736485148572E-05"
        izz="0.00973951348382178" />
    </inertial>
    <visual>
      <origin xyz="0 0 0" rpy="0 0 0" />
      <geometry>
        <mesh
          filename="package://ino_ir_400_4/meshes/baselink.dae" />
      </geometry>
      <material
        name="">
        <color
          rgba="0.792156862745098 0.819607843137255 0.933333333333333 1" />
      </material>
    </visual>
    <collision>
      <origin xyz="0 0 0" rpy="0 0 0" />
      <geometry>
        <mesh
          filename="package://ino_ir_400_4/meshes/baselink.obj" />
      </geometry>
    </collision>
  </link>
  <link name="link1">
    <inertial>
      <origin xyz="0.100762422197871 -4.15879641913283E-06 0.0430096798259152" rpy="0 0 0" />
      <mass
        value="1.04914101414795" />
      <inertia
        ixx="0.000790470115287701"
        ixy="4.96914433097863E-08"
        ixz="4.6837895291801E-05"
        iyy="0.00844429805643474"
        iyz="-7.48336244503902E-09"
        izz="0.0089607919678015" />
    </inertial>
    <visual>
      <origin
        xyz="0 0 0"
        rpy="0 0 0" />
      <geometry>
        <mesh
          filename="package://ino_ir_400_4/meshes/link1.dae" />
      </geometry>
      <material
        name="">
        <color
          rgba="1 1 1 1" />
      </material>
    </visual>
    <collision>
      <origin xyz="0 0 0"  rpy="0 0 0" />
      <geometry>
        <mesh
          filename="package://ino_ir_400_4/meshes/link1.obj" />
      </geometry>
    </collision>
  </link>
  <joint name="joint1" type="revolute">
    <origin xyz="0 0 0" rpy="0 0 0" />
    <parent
      link="baselink" />
    <child
      link="link1" />
    <axis
      xyz="0 0 1" />
    <limit lower="-1.6" upper="1.6" effort="40" velocity="6.2832" />
  </joint>
  <link name="link2">
    <inertial>
      <origin xyz="0.0692345179040184 -1.36553873458821E-06 0.0948639235249834" rpy="0 0 0" />
      <mass
        value="4.37140972916236" />
      <inertia
        ixx="0.0164443431821456"
        ixy="-4.4524412352778E-07"
        ixz="0.00180305389582797"
        iyy="0.0316170708085011"
        iyz="-1.10803964728059E-08"
        izz="0.0225919113178935" />
    </inertial>
    <visual>
      <origin xyz="0 0 0" rpy="0 0 0" />
      <geometry>
        <mesh
          filename="package://ino_ir_400_4/meshes/link2.dae" />
      </geometry>
      <material
        name="">
        <color
          rgba="0.792156862745098 0.819607843137255 0.933333333333333 1" />
      </material>
    </visual>
    <collision>
      <origin xyz="0 0 0" rpy="0 0 0" />
      <geometry>
        <mesh
          filename="package://ino_ir_400_4/meshes/link2.obj" />
      </geometry>
    </collision>
  </link>
  <joint name="joint2" type="revolute">
    <origin xyz="0.225 0 0.0614" rpy="0 0 0" />
    <parent
      link="link1" />
    <child
      link="link2" />
    <axis
      xyz="0 0 1" />
    <limit lower="-2.4609" upper="2.4609" effort="30" velocity="6.2832" />
  </joint>
  <link name="link3">
    <inertial>
      <origin
        xyz="8.08936534032467E-05 -2.50765281707626E-05 0.2047079329259"
        rpy="0 0 0" />
      <mass
        value="0.0353721198227354" />
      <inertia
        ixx="0.000307906325822679"
        ixy="-2.25976534063343E-09"
        ixz="-3.75701332087269E-07"
        iyy="0.00030788513534791"
        iyz="1.16283323361547E-07"
        izz="2.01279425582973E-06" />
    </inertial>
    <visual>
      <origin
        xyz="0 0 0"
        rpy="0 0 0" />
      <geometry>
        <mesh
          filename="package://ino_ir_400_4/meshes/link3.dae" />
      </geometry>
      <material
        name="">
        <color
          rgba="0.792156862745098 0.819607843137255 0.933333333333333 1" />
      </material>
    </visual>
    <collision>
      <origin
        xyz="0 0 0"
        rpy="0 0 0" />
      <geometry>
        <mesh
          filename="package://ino_ir_400_4/meshes/link3.obj" />
      </geometry>
    </collision>
  </link>
  <joint name="joint3" type="prismatic">
    <origin
      xyz="0.175 0 -0.0614"
      rpy="0 0 0" />
    <parent
      link="link2" />
    <child
      link="link3" />
    <axis
      xyz="0 0 1" />
    <limit lower="-0.04" upper="0" effort="20" velocity="1.3" />
  </joint>
  <link name="link4">
    <inertial>
      <origin
        xyz="0.000269193867090345 -3.65915253696762E-05 0.0275835344641969"
        rpy="0 0 0" />
      <mass
        value="0.00843880884560637" />
      <inertia
        ixx="1.48872682222414E-06"
        ixy="-2.6264753474242E-09"
        ixz="-2.506635428181E-08"
        iyy="1.45655449640398E-06"
        iyz="2.29160751505996E-09"
        izz="8.05120659155988E-07" />
    </inertial>
    <visual>
      <origin
        xyz="0 0 0"
        rpy="0 0 0" />
      <geometry>
        <mesh
          filename="package://ino_ir_400_4/meshes/link4.dae" />
      </geometry>
      <material
        name="">
        <color
          rgba="0.792156862745098 0.819607843137255 0.933333333333333 1" />
      </material>
    </visual>
    <collision>
      <origin
        xyz="0 0 0"
        rpy="0 0 0" />
      <geometry>
        <mesh
          filename="package://ino_ir_400_4/meshes/link4.obj" />
      </geometry>
    </collision>
  </link>
  <joint name="joint4" type="revolute">
    <origin xyz="0 0 0" rpy="0 0 0" />
    <parent link="link3" />
    <child link="link4" />
    <axis xyz="0 0 1" />
    <limit lower="-1.1416" upper="1.1416" effort="10" velocity="45.379" />
  </joint>
  <link name="link5">
    <inertial>
      <origin
        xyz="0.000269193867090345 -3.65915253696762E-05 0.0275835344641969"
        rpy="0 0 0" />
      <mass
        value="0.00843880884560637" />
      <inertia
        ixx="1.48872682222414E-06"
        ixy="-2.6264753474242E-09"
        ixz="-2.506635428181E-08"
        iyy="1.45655449640398E-06"
        iyz="2.29160751505996E-09"
        izz="8.05120659155988E-07" />
    </inertial>
    <visual>
      <origin
        xyz="0 0 0"
        rpy="0 0 0" />
      <geometry>
        <mesh
          filename="package://ino_ir_400_4/meshes/mylink.dae" />
      </geometry>
      <material
        name="">
        <color
          rgba="0.792156862745098 0.819607843137255 0.933333333333333 1" />
      </material>
    </visual>
    <collision>
      <origin
        xyz="0 0 0"
        rpy="0 0 0" />
      <geometry>
        <mesh
          filename="package://ino_ir_400_4/meshes/mylink.obj" />
      </geometry>
    </collision>
  </link>
  <joint name="joint5" type="revolute">
    <origin xyz="0 0 0" rpy="0 0 0" />
    <parent link="link4" />
    <child link="link5" />
    <axis xyz="0 0 1" />
    <limit lower="0" upper="0" effort="1" velocity="1" />
  </joint>
  <link name="link6">
        <inertial>
      <origin
        xyz="0.000269193867090345 -3.65915253696762E-05 0.0275835344641969"
        rpy="0 0 0" />
      <mass
        value="0.00843880884560637" />
      <inertia
        ixx="1.48872682222414E-06"
        ixy="-2.6264753474242E-09"
        ixz="-2.506635428181E-08"
        iyy="1.45655449640398E-06"
        iyz="2.29160751505996E-09"
        izz="8.05120659155988E-07" />
    </inertial>
    <visual>
      <origin
        xyz="0 0 0"
        rpy="0 0 0" />
      <geometry>
        <mesh
          filename="package://ino_ir_400_4/meshes/mylink.dae" />
      </geometry>
      <material
        name="">
        <color
          rgba="0.792156862745098 0.819607843137255 0.933333333333333 1" />
      </material>
    </visual>
    <collision>
      <origin
        xyz="0 0 0"
        rpy="0 0 0" />
      <geometry>
        <mesh
          filename="package://ino_ir_400_4/meshes/mylink.obj" />
      </geometry>
    </collision>
  </link>
  <joint name="joint6" type="revolute">
    <origin xyz="0 0 0" rpy="0 0 0" />
    <parent link="link5" />
    <child link="link6" />
    <axis xyz="0 0 1" />
    <limit lower="0" upper="0" effort="1" velocity="1" />
  </joint>

  <joint name="hand_joint" type="fixed">
    <origin rpy="0 0 0" xyz="0 0 0.03"/>
    <parent link="link6"/>
    <child link="hand_base_link"/>
  </joint>
  <link name="hand_base_link">
    <inertial>
      <origin xyz="0.017069 0.097417 -0.14989" rpy="0 0 0" />
      <mass
        value="0.36645" />
      <inertia
        ixx="0.00042998"
        ixy="-5.8464E-08"
        ixz="-3.871E-07"
        iyy="0.00045575"
        iyz="4.0823E-05"
        izz="9.9563E-05" />
    </inertial>
    <visual>
      <origin xyz="0 0 0" rpy="0 0 0" />
      <geometry>
        <mesh filename="package://ino_ir_400_4/meshes/hand_base_link.dae" />
      </geometry>
      <material name="">
        <color rgba="0.75294 0.75294 0.75294 1" />
      </material>
    </visual>
    <collision>
      <origin xyz="0 0 0" rpy="0 0 0" />
      <geometry>
        <mesh filename="package://ino_ir_400_4/meshes/hand_base_link.obj" />
      </geometry>
    </collision>
  </link>
  <link name="left_finger">
    <inertial>
      <origin xyz="-8.6431E-09 -0.00083316 -0.018002" rpy="0 0 0" />
      <mass value="0.003611" />
      <inertia ixx="6.6075E-07" ixy="-7.8915E-14" ixz="-3.472E-13"
        iyy="6.0227E-07" iyz="-1.8484E-07" izz="1.735E-07" />
    </inertial>
    <visual>
      <origin xyz="0 0 0" rpy="0 0 0" />
      <geometry>
        <mesh filename="package://ino_ir_400_4/meshes/left_finger.dae" />
      </geometry>
      <material
        name="">
        <color rgba="1 0 0 1" />
      </material>
    </visual>
    <collision>
      <origin xyz="0 0 0" rpy="0 0 0" />
      <geometry>
        <mesh
          filename="package://ino_ir_400_4/meshes/left_finger.obj" />
      </geometry>
      <sdf resolution="256"/>
    </collision>
  </link>
  <joint name="left_finger_joint" type="prismatic">
    <origin xyz="0.0408 0.0166 -0.2236" rpy="0 0 0" />
    <parent link="hand_base_link" />
    <child link="left_finger" />
    <axis  xyz="0 1 0" />
    <dynamics damping="10.0"/>
    <limit lower="0" upper="0.01" effort="1" velocity="1" />
  </joint>
  <link name="left_tip">
    <collision>
      <geometry>
        <box size="0.013 0.004 0.013"/>
      </geometry>
    </collision>
  </link>
  <joint name="leftfinger_tip_joint" type="fixed">
    <origin xyz="0 -0.0166 -0.042513" rpy="0 0 0" />
    <parent link="left_finger" />
    <child link="left_tip" />
    <axis xyz="0 0 0" />
  </joint>
  <link name="right_finger">
    <inertial>
      <origin
        xyz="8.6276E-09 0.00083443 -0.018004"
        rpy="0 0 0" />
      <mass
        value="0.0036113" />
      <inertia
        ixx="6.6105E-07"
        ixy="-7.8497E-14"
        ixz="3.4673E-13"
        iyy="6.0249E-07"
        iyz="1.8496E-07"
        izz="1.7357E-07" />
    </inertial>
    <visual>
      <origin
        xyz="0 0 0"
        rpy="0 0 0" />
      <geometry>
        <mesh
          filename="package://ino_ir_400_4/meshes/right_finger.dae" />
      </geometry>
      <material
        name="">
        <color
          rgba="1 0 0 1" />
      </material>
    </visual>
    <collision>
      <origin
        xyz="0 0 0"
        rpy="0 0 0" />
      <geometry>
        <mesh
          filename="package://ino_ir_400_4/meshes/right_finger.obj" />
      </geometry>
      <sdf resolution="256"/>
    </collision>
  </link>
  <joint name="right_finger_joint" type="prismatic">
    <origin xyz="0.0408 -0.0166 -0.2236" rpy="0 0 0" />
    <parent
      link="hand_base_link" />
    <child
      link="right_finger" />
    <axis xyz="0 -1 0" />
    <dynamics damping="10.0"/>
    <limit lower="0" upper="0.01" effort="1" velocity="1" />
	  <mimic joint="left_finger_joint"/>
  </joint>
  <link name="right_tip">
    <collision>
      <geometry>
        <box size="0.013 0.004 0.013"/>
      </geometry>
    </collision>
  </link>
  <joint name="rightfinger_tip_joint" type="fixed">
    <origin xyz="0 0.016 -0.042513" rpy="0 0 0" />
    <parent link="right_finger" />
    <child link="right_tip" />
    <axis xyz="0 0 0" />
  </joint>
  <joint name="grip_vis_joint" type="fixed">
    <parent link="hand_base_link"/>
    <child link="grip_site"/>
    <origin rpy="0 0 0" xyz="0.0408 0 -0.2661"/>
  </joint>
  <link name="grip_site">
    <visual>
      <geometry>
        <sphere radius="0.001"/>
      </geometry>
      <material name="Vis"/>
    </visual>
  </link>
  <link name="cam">
    <inertial>
      <origin
        xyz="-8.5017E-05 -7.8981E-05 -0.011294"
        rpy="0 0 0" />
      <mass
        value="1.0768" />
      <inertia
        ixx="0.00019743"
        ixy="1.1236E-08"
        ixz="-2.9652E-07"
        iyy="0.00019719"
        iyz="-4.1694E-07"
        izz="0.00030137" />
    </inertial>
    <visual>
      <origin
        xyz="0 0 0"
        rpy="0 0 0" />
      <geometry>
        <mesh
          filename="package://ino_ir_400_4/meshes/cam.dae" />
      </geometry>
      <material
        name="">
        <color
          rgba="1 0.94118 0.67843 1" />
      </material>
    </visual>
    <collision>
      <origin
        xyz="0 0 0"
        rpy="0 0 0" />
      <geometry>
        <mesh
          filename="package://ino_ir_400_4/meshes/cam.obj" />
      </geometry>
    </collision>
  </link>
  <joint name="cam_joint" type="fixed">
    <origin xyz="-0.0656439049555634 0 -0.198939887726928" rpy="2.3562 0 1.5707963267949" />
    <parent link="hand_base_link" />
    <child link="cam" />
    <axis xyz="0 0 0" />
  </joint>
  <link name="cam_point">
    <visual>
      <geometry>
        <sphere radius="0.001"/>
      </geometry>
      <material name="Vis"/>
    </visual>
  </link>
  <joint name="jointcam" type="fixed">
    <origin xyz="0 0 0" rpy="0 0 0" />
    <parent link="cam" />
    <child link="cam_point" />
    <axis xyz="0 0 0" />
  </joint>

  <link name="env">
    <inertial>
      <origin
        xyz="0.257938872246366 0.202440227265669 -0.182038064498453"
        rpy="0 0 0" />
      <mass
        value="70.3565754713384" />
      <inertia
        ixx="5.29398784227613"
        ixy="-0.1290981341927"
        ixz="-0.0808665282809915"
        iyy="5.19440647934511"
        iyz="0.0041547269468774"
        izz="9.78932300844001" />
    </inertial>
    <visual>
      <origin xyz="0 0 0" rpy="0 0 0" />
      <geometry>
        <mesh
          filename="package://ino_ir_400_4/meshes/env.dae" />
      </geometry>
      <material
        name="">
        <color
          rgba="0.752941176470588 0.752941176470588 0.752941176470588 1" />
      </material>
    </visual>
    <collision>
      <origin xyz="0 0 0" rpy="0 0 0" />
      <geometry>
        <mesh
          filename="package://ino_ir_400_4/meshes/env.obj" />
      </geometry>
    </collision>
  </link>
  <link name="platform">
    <inertial>
      <origin
        xyz="0.0107383685001534 -0.0610234383836579 -0.0156891844474306"
        rpy="0 0 0" />
      <mass
        value="0.380074879750474" />
      <inertia
        ixx="0.000715943222370812"
        ixy="1.24916082448569E-06"
        ixz="1.13762873105386E-06"
        iyy="0.000395971821601958"
        iyz="-2.02787883823606E-06"
        izz="0.00110044119676599" />
    </inertial>
    <visual>
      <origin xyz="0 0 0" rpy="0 0 0" />
      <geometry>
        <mesh
          filename="package://ino_ir_400_4/meshes/platform.dae" />
      </geometry>
      <material
        name="">
        <color
          rgba="0.752941176470588 0.752941176470588 0.752941176470588 1" />
      </material>
    </visual>
    <collision>
      <origin xyz="0 0 0" rpy="0 0 0" />
      <geometry>
        <mesh
          filename="package://ino_ir_400_4/meshes/platform.obj" />
      </geometry>
    </collision>
  </link>
  <joint name="env_platform" type="fixed">
    <origin
      xyz="0.340987103481122 0.112814884975291 -0.115"
      rpy="0 0 0" />
    <parent
      link="env" />
    <child
      link="platform" />
    <axis
      xyz="0 0 0" />
  </joint>
  <joint name="base_link-base_fixed_joint" type="fixed">
    <origin rpy="0 0 0" xyz="0.023 0 0.1468"/>
    <parent link="env"/>
    <child link="baselink"/>
  </joint>
</robot>
