<?xml version="1.0" ?>
<!-- =================================================================================== -->
<!-- |    This document was autogenerated by xacro from ur5_robot.urdf.xacro           | -->
<!-- |    EDITING THIS FILE BY HAND IS NOT RECOMMENDED                                 | -->
<!-- =================================================================================== -->
<robot name="ur5" xmlns:xacro="http://wiki.ros.org/xacro">
  <link name="base_link">
    <visual>
      <geometry>
        <mesh filename="package://ur5/meshes/ur5/visual/base.dae"/>
      </geometry>
      <material name="LightGrey">
        <color rgba="0.7 0.7 0.7 1.0"/>
      </material>
    </visual>
    <collision>
      <geometry>
        <mesh filename="package://ur5/meshes/ur5/collision/base.obj"/>
      </geometry>
    </collision>
    <inertial>
      <mass value="4.0"/>
      <origin rpy="0 0 0" xyz="0.0 0.0 0.0"/>
      <inertia ixx="0.00443333156" ixy="0.0" ixz="0.0" iyy="0.00443333156" iyz="0.0" izz="0.0072"/>
    </inertial>
  </link>
  <joint name="shoulder_pan_joint" type="revolute">
    <parent link="base_link"/>
    <child link="shoulder_link"/>
    <origin rpy="0.0 0.0 0.0" xyz="0.0 0.0 0.089159"/>
    <axis xyz="0 0 1"/>
    <limit effort="150.0" lower="-3.14159265359" upper="3.14159265359" velocity="3.15"/>
    <dynamics damping="0.0" friction="0.0"/>
  </joint>
  <link name="shoulder_link">
    <visual>
      <geometry>
        <mesh filename="package://ur5/meshes/ur5/visual/shoulder.dae"/>
      </geometry>
      <material name="LightGrey">
        <color rgba="0.7 0.7 0.7 1.0"/>
      </material>
    </visual>
    <collision>
      <geometry>
        <mesh filename="package://ur5/meshes/ur5/collision/shoulder.obj"/>
      </geometry>
    </collision>
    <inertial>
      <mass value="3.7"/>
      <origin rpy="0 0 0" xyz="0.0 0.0 0.0"/>
      <inertia ixx="0.010267495893" ixy="0.0" ixz="0.0" iyy="0.010267495893" iyz="0.0" izz="0.00666"/>
    </inertial>
  </link>
  <joint name="shoulder_lift_joint" type="revolute">
    <parent link="shoulder_link"/>
    <child link="upper_arm_link"/>
    <origin rpy="0.0 1.57079632679 0.0" xyz="0.0 0.13585 0.0"/>
    <axis xyz="0 1 0"/>
    <limit effort="150.0" lower="-3.14159265359" upper="3.14159265359" velocity="3.15"/>
    <dynamics damping="0.0" friction="0.0"/>
  </joint>
  <link name="upper_arm_link">
    <visual>
      <geometry>
        <mesh filename="package://ur5/meshes/ur5/visual/upperarm.dae"/>
      </geometry>
      <material name="LightGrey">
        <color rgba="0.7 0.7 0.7 1.0"/>
      </material>
    </visual>
    <collision>
      <geometry>
        <mesh filename="package://ur5/meshes/ur5/collision/upperarm.obj"/>
      </geometry>
    </collision>
    <inertial>
      <mass value="8.393"/>
      <origin rpy="0 0 0" xyz="0.0 0.0 0.28"/>
      <inertia ixx="0.22689067591" ixy="0.0" ixz="0.0" iyy="0.22689067591" iyz="0.0" izz="0.0151074"/>
    </inertial>
  </link>
  <joint name="elbow_joint" type="revolute">
    <parent link="upper_arm_link"/>
    <child link="forearm_link"/>
    <origin rpy="0.0 0.0 0.0" xyz="0.0 -0.1197 0.425"/>
    <axis xyz="0 1 0"/>
    <limit effort="150.0" lower="-3.14159265359" upper="3.14159265359" velocity="3.15"/>
    <dynamics damping="0.0" friction="0.0"/>
  </joint>
  <link name="forearm_link">
    <visual>
      <geometry>
        <mesh filename="package://ur5/meshes/ur5/visual/forearm.dae"/>
      </geometry>
      <material name="LightGrey">
        <color rgba="0.7 0.7 0.7 1.0"/>
      </material>
    </visual>
    <collision>
      <geometry>
        <mesh filename="package://ur5/meshes/ur5/collision/forearm.obj"/>
      </geometry>
    </collision>
    <inertial>
      <mass value="2.275"/>
      <origin rpy="0 0 0" xyz="0.0 0.0 0.196125"/>
      <inertia ixx="0.0312167910289" ixy="0.0" ixz="0.0" iyy="0.0312167910289" iyz="0.0" izz="0.004095"/>
    </inertial>
  </link>
  <joint name="wrist_1_joint" type="revolute">
    <parent link="forearm_link"/>
    <child link="wrist_1_link"/>
    <origin rpy="0.0 1.57079632679 0.0" xyz="0.0 0.0 0.39225"/>
    <axis xyz="0 1 0"/>
    <limit effort="28.0" lower="-3.14159265359" upper="3.14159265359" velocity="3.2"/>
    <dynamics damping="0.0" friction="0.0"/>
  </joint>
  <link name="wrist_1_link">
    <visual>
      <geometry>
        <mesh filename="package://ur5/meshes/ur5/visual/wrist1.dae"/>
      </geometry>
      <material name="LightGrey">
        <color rgba="0.7 0.7 0.7 1.0"/>
      </material>
    </visual>
    <collision>
      <geometry>
        <mesh filename="package://ur5/meshes/ur5/collision/wrist1.obj"/>
      </geometry>
    </collision>
    <inertial>
      <mass value="1.219"/>
      <origin rpy="0 0 0" xyz="0.0 0.093 0.0"/>
      <inertia ixx="0.00255989897604" ixy="0.0" ixz="0.0" iyy="0.00255989897604" iyz="0.0" izz="0.0021942"/>
    </inertial>
  </link>
  <joint name="wrist_2_joint" type="revolute">
    <parent link="wrist_1_link"/>
    <child link="wrist_2_link"/>
    <origin rpy="0.0 0.0 0.0" xyz="0.0 0.093 0.0"/>
    <axis xyz="0 0 1"/>
    <limit effort="28.0" lower="-3.14159265359" upper="3.14159265359" velocity="3.2"/>
    <dynamics damping="0.0" friction="0.0"/>
  </joint>
  <link name="wrist_2_link">
    <visual>
      <geometry>
        <mesh filename="package://ur5/meshes/ur5/visual/wrist2.dae"/>
      </geometry>
      <material name="LightGrey">
        <color rgba="0.7 0.7 0.7 1.0"/>
      </material>
    </visual>
    <collision>
      <geometry>
        <mesh filename="package://ur5/meshes/ur5/collision/wrist2.obj"/>
      </geometry>
    </collision>
    <inertial>
      <mass value="1.219"/>
      <origin rpy="0 0 0" xyz="0.0 0.0 0.09465"/>
      <inertia ixx="0.00255989897604" ixy="0.0" ixz="0.0" iyy="0.00255989897604" iyz="0.0" izz="0.0021942"/>
    </inertial>
  </link>
  <joint name="wrist_3_joint" type="revolute">
    <parent link="wrist_2_link"/>
    <child link="wrist_3_link"/>
    <origin rpy="0.0 0.0 0.0" xyz="0.0 0.0 0.09465"/>
    <axis xyz="0 1 0"/>
    <limit effort="28.0" lower="-3.14159265359" upper="3.14159265359" velocity="3.2"/>
    <dynamics damping="0.0" friction="0.0"/>
  </joint>
  <link name="wrist_3_link">
    <visual>
      <geometry>
        <mesh filename="package://ur5/meshes/ur5/visual/wrist3.dae"/>
      </geometry>
      <material name="LightGrey">
        <color rgba="0.7 0.7 0.7 1.0"/>
      </material>
    </visual>
    <collision>
      <geometry>
        <mesh filename="package://ur5/meshes/ur5/collision/wrist3.obj"/>
      </geometry>
    </collision>
    <inertial>
      <mass value="0.1879"/>
      <origin rpy="1.57079632679 0 0" xyz="0.0 0.06505 0.0"/>
      <inertia ixx="8.46958911216e-05" ixy="0.0" ixz="0.0" iyy="8.46958911216e-05" iyz="0.0" izz="0.0001321171875"/>
    </inertial>
  </link>

  <link name="base"/>
  <joint name="base_link-base_fixed_joint" type="fixed">
    <origin rpy="0 0 -3.14159265359" xyz="0 0 0"/>
    <parent link="base_link"/>
    <child link="base"/>
  </joint>
  
  <link name="tool0"/>
  <joint name="wrist_3_link-tool0_fixed_joint" type="fixed">
    <origin rpy="-1.57079632679 0 0" xyz="0 0.0823 0"/>
    <parent link="wrist_3_link"/>
    <child link="tool0"/>
  </joint>
  <joint name="hand_joint" type="fixed">
    <origin rpy="0 0 1.5707" xyz="0 0 0"/>
    <parent link="tool0"/>
    <child link="hand_base_link"/>
  </joint>

  <link name="hand_base_link">
    <inertial>
      <origin
        xyz="2.87706262272012E-05 0.00218479828314205 0.0350928713955748"
        rpy="0 0 0" />
      <mass
        value="0.415638983663421" />
      <inertia
        ixx="0.000396533135403228"
        ixy="-1.97625400107318E-08"
        ixz="2.15168193507134E-08"
        iyy="0.000196216356205772"
        iyz="-2.95609188452226E-07"
        izz="0.000433341395250827" />
    </inertial>
    <visual>
      <origin
        xyz="0 0 0"
        rpy="0 0 0" />
      <geometry>
        <mesh
          filename="package://ur5/meshes/hand.dae" />
      </geometry>
      <material
        name="">
        <color
          rgba="0.792156862745098 0.819607843137255 0.933333333333333 1" />
      </material>
    </visual>
    <collision>
      <origin
        xyz="0 0 0"
        rpy="0 0 0" />
      <geometry>
        <mesh
          filename="package://ur5/meshes/hand.obj" />
      </geometry>
    </collision>
  </link>
  <link name="left_finger">
    <inertial>
      <origin
        xyz="0.0092134924632298 -0.00194790394990391 -0.0176274897759977"
        rpy="0 0 0" />
      <mass
        value="0.0589543896992846" />
      <!-- <inertia
        ixx="3.37272907966156E-05"
        ixy="3.83269385718325E-06"
        ixz="-4.62772008724202E-06"
        iyy="2.37128965154064E-05"
        iyz="4.94815116549899E-06"
        izz="1.98369145830284E-05" /> -->
    </inertial>
    <visual>
      <origin
        xyz="0 0 0"
        rpy="0 0 0" />
      <geometry>
        <mesh
          filename="package://ur5/meshes/finger.dae" />
      </geometry>
      <material
        name="">
        <color
          rgba="0.792156862745098 0.819607843137255 0.933333333333333 1" />
      </material>
    </visual>
    <collision>
      <origin
        xyz="0 0 0"
        rpy="0 0 0" />
      <geometry>
        <mesh
          filename="package://ur5/meshes/finger.obj" />
      </geometry>
    </collision>
  </link>
  <link name="right_finger">
    <inertial>
      <origin
        xyz="0.00921349246322973 -0.00194790394990389 -0.0176274897759977"
        rpy="0 0 0" />
      <mass
        value="0.0589543896992846" />
      <!-- <inertia
        ixx="3.37272907966157E-05"
        ixy="3.83269385718325E-06"
        ixz="-4.62772008724202E-06"
        iyy="2.37128965154064E-05"
        iyz="4.94815116549898E-06"
        izz="1.98369145830284E-05" /> -->
    </inertial>
    <visual>
      <origin xyz="0 0 0" rpy="0 0 3.14159265359" />
      <geometry>
        <mesh
          filename="package://ur5/meshes/finger.dae"/>
      </geometry>
      <material
        name="">
        <color
          rgba="0.792156862745098 0.819607843137255 0.933333333333333 1" />
      </material>
    </visual>
    <collision>
      <origin xyz="0 0 0" rpy="0 0 3.14159265359" />
      <geometry>
        <mesh
          filename="package://ur5/meshes/finger.obj" />
      </geometry>
    </collision>
  </link>
  <joint name="left_finger_joint" type="prismatic">
    <origin xyz="0 0 0.0851" rpy="0 3.14159 3.14159" />
    <parent link="hand_base_link" />
    <child link="left_finger" />
    <axis xyz="0 1 0" />
	  <dynamics damping="10.0"/>
    <limit lower="0.0" upper="0.04" effort="140" velocity="0.036" />
  </joint>
  <joint name="right_finger_joint" type="prismatic">
    <origin  xyz="0 0 0.0851" rpy="0 3.14159 3.14159" />
    <parent link="hand_base_link" />
    <child link="right_finger" />
    <axis xyz="0 -1 0" />
	  <dynamics damping="10.0"/>
    <limit lower="0.0" upper="0.04" effort="140" velocity="0.036" />
	  <mimic joint="left_finger_joint"/>
  </joint>
   <joint name="grip_vis_joint" type="fixed">
    <parent link="hand_base_link"/>
    <child link="grip_site"/>
    <origin rpy="0 0 0" xyz="0 0 0.1425"/>
  </joint>
  <link name="grip_site">
    <visual>
      <geometry>
        <sphere radius="0.005"/>
      </geometry>
      <material name="Vis"/>
    </visual>
  </link>
  <joint name="leftfinger_tip_joint" type="fixed">
    <parent link="left_finger"/>
    <child link="leftfinger_tip"/>
    <origin rpy="0 3.14159 3.14159 " xyz="0 0.002 -0.0574"/>
  </joint>
  <link name="leftfinger_tip">
    <collision>
      <geometry>
        <box size="0.013 0.004 0.013"/>
      </geometry>
    </collision>
  </link>
  <joint name="rightfinger_tip_joint" type="fixed">
    <parent link="right_finger"/>
    <child link="rightfinger_tip"/>
    <origin rpy="0 3.14159 3.14159" xyz="0 -0.002 -0.0574"/>
  </joint>
  <link name="rightfinger_tip">
    <collision>
      <geometry>
        <box size="0.013 0.004 0.013"/>
      </geometry>
    </collision>
  </link>
</robot>

